Workbook

Sheet Start Here
A1: OfficerOS Budget Sheet (Hybrid)
A2: Pre-filled for military pay. Change only the blue input cells. Monthly view.
A4: Inputs | D4: Monthly Pay (auto-filled from OfficerOS export) | G4: Hybrid Budget Targets (editable)
A5: Year | B5: 2026 | D5: Base Pay (taxable) | E5: 0 | G5: Housing target = % of BAH | H5: 1
A6: Pay Grade (e.g., O-1, E-5) | B6: O-1 | D6: BAH (usually non-taxable) | E6: 0 | G6: Food target = % of BAS | H6: 1
A7: Years of Service bracket | B7: < 2 | D7: BAS (usually non-taxable) | E7: 0 | G7: Minimum savings rate | H7: 0.2
A8: Duty ZIP (5-digit) | B8: 02139 | D8: Other Income (manual) | E8: 0
A9: With dependents? (TRUE/FALSE) | B9: FALSE | C9: Select TRUE for with-dependents BAH. | D9: Total Monthly Income | E9: =SUM(E5:E8) | G9: Suggested Housing Budget | H9: =E6*H5
A10: State income tax rate (optional) | B10: 0 | C10: Optional: rough estimate. Federal taxes not modeled. | G10: Suggested Food Budget | H10: =E7*H6
A11: TSP contribution % (0-1) | B11: 0.1 | C11: Optional: used for suggested TSP line item. | D11: Estimated State Tax (rough) | E11: =E5*B10 | G11: Suggested Minimum Savings | H11: =E9*H7
A12: Roth/Traditional note | B12: Roth / Traditional (your choice) | D12: Net After State Tax (rough) | E12: =E9-E11
A14: Notes
A15: • Base Pay is taxable. BAH/BAS are typically non-taxable for most service members. • This workbook is monthly. Blue cells are for your inputs. • Hybrid approach: Housing target ties to BAH, Food ties to BAS, and Savings uses a baseline rate. • You can still override any line item in the Budget tab.

Sheet Budget
A1: Monthly Budget
A2: Plan vs Actual. Blue cells are your inputs. Totals & Remaining update automatically.
A4: Monthly Income (from Start Here)
A5: Category | B5: Planned | C5: Actual | D5: Diff
A6: Income | B6: ='Start Here'!E9 | C6: ='Start Here'!E9 | D6: =C6-B6
A8: Category | B8: Planned | C8: Actual | D8: Diff
A9: HOUSING (targeted to BAH)
A10: Rent / Mortgage | B10: ='Start Here'!H9 | C10: 0 | D10: =C10-B10
A11: Renter/Home Insurance | B11: 0 | C11: 0 | D11: =C11-B11
A12: Utilities (electric/gas/water) | B12: 0 | C12: 0 | D12: =C12-B12
A13: Internet | B13: 0 | C13: 0 | D13: =C13-B13
A14: HOA / Fees | B14: 0 | C14: 0 | D14: =C14-B14
A15: Maintenance / Repairs | B15: 0 | C15: 0 | D15: =C15-B15
A16: Section Total | B16: =SUM(B10:B15) | C16: =SUM(C10:C15) | D16: =C16-B16
A18: FOOD (targeted to BAS)
A19: Groceries | B19: ='Start Here'!H10 | C19: 0 | D19: =C19-B19
A20: Dining Out | B20: 0 | C20: 0 | D20: =C20-B20
A21: Coffee / Snacks | B21: 0 | C21: 0 | D21: =C21-B21
A22: Section Total | B22: =SUM(B19:B21) | C22: =SUM(C19:C21) | D22: =C22-B22
A24: TRANSPORTATION
A25: Car payment | B25: 0 | C25: 0 | D25: =C25-B25
A26: Gas / Transit | B26: 0 | C26: 0 | D26: =C26-B26
A27: Car insurance | B27: 0 | C27: 0 | D27: =C27-B27
A28: Parking / Tolls | B28: 0 | C28: 0 | D28: =C28-B28
A29: Maintenance | B29: 0 | C29: 0 | D29: =C29-B29
A30: Section Total | B30: =SUM(B25:B29) | C30: =SUM(C25:C29) | D30: =C30-B30
A32: HEALTH & INSURANCE
A33: Medical / Dental out-of-pocket | B33: 0 | C33: 0 | D33: =C33-B33
A34: Gym / Fitness | B34: 0 | C34: 0 | D34: =C34-B34
A35: Life insurance | B35: 0 | C35: 0 | D35: =C35-B35
A36: Section Total | B36: =SUM(B33:B35) | C36: =SUM(C33:C35) | D36: =C36-B36
A38: DEBT PAYDOWN
A39: Credit cards (beyond minimum) | B39: 0 | C39: 0 | D39: =C39-B39
A40: Student loans | B40: 0 | C40: 0 | D40: =C40-B40
A41: Personal/Auto loan extra | B41: 0 | C41: 0 | D41: =C41-B41
A42: Section Total | B42: =SUM(B39:B41) | C42: =SUM(C39:C41) | D42: =C42-B42
A44: SAVINGS & INVESTING (targeted to min savings)
A45: TSP (auto from %) | B45: ='Start Here'!E5*'Start Here'!B11 | C45: 0 | D45: =C45-B45
A46: Roth IRA / IRA | B46: 0 | C46: 0 | D46: =C46-B46
A47: Brokerage | B47: 0 | C47: 0 | D47: =C47-B47
...

Sheet Bills & Due Dates
A1: Bills & Due Dates
A2: Track recurring bills so your budget is predictable. Fill in the blue cells.
A4: Bill | B4: Amount | C4: Due Day | D4: Autopay? | E4: Account | F4: Category | G4: Notes
A5: Rent/Mortgage | D5: TRUE | F5: Housing
A6: Utilities | D6: FALSE | F6: Housing
A7: Internet | D7: TRUE | F7: Housing
A8: Phone | D8: TRUE | F8: Other
A9: Car payment | D9: TRUE | F9: Transportation
A10: Car insurance | D10: TRUE | F10: Transportation
A11: Subscriptions | D11: TRUE | F11: Wants
A20: Total Monthly Bills | B20: =SUM(B5:B200)

Sheet Goals
A1: Goals
A2: Turn big goals into a timeline. Fill in blue inputs; timeline updates automatically.
A4: Goal | B4: Target ($) | C4: Current ($) | D4: Monthly ($) | E4: Months to Goal | F4: Notes
A5: Starter emergency fund | B5: 1000 | C5: 0 | D5: 50 | E5: =IF(D5<=0,"",IF(B5<=C5,0,CEILING((B5-C5)/D5,1)))
A6: 1 month expenses | B6: 3000 | C6: 0 | D6: 200 | E6: =IF(D6<=0,"",IF(B6<=C6,0,CEILING((B6-C6)/D6,1)))
A7: Pay off high-interest debt | B7: 2000 | C7: 0 | D7: 150 | E7: =IF(D7<=0,"",IF(B7<=C7,0,CEILING((B7-C7)/D7,1)))
A8: Down payment / house fund | B8: 20000 | C8: 0 | D8: 500 | E8: =IF(D8<=0,"",IF(B8<=C8,0,CEILING((B8-C8)/D8,1)))
A9: Big purchase (car/PCS) | B9: 5000 | C9: 0 | D9: 150 | E9: =IF(D9<=0,"",IF(B9<=C9,0,CEILING((B9-C9)/D9,1)))

Sheet Dashboard
A1: Dashboard
A2: Quick visuals to understand your pay and plan at a glance.
A4: Key Numbers (Monthly) | F4: Income Breakdown
A5: Total Income | B5: ='Start Here'!E9 | F5: Component | G5: Amount
A6: Planned Spending | B6: ='Budget'!B72 | F6: Base Pay | G6: ='Start Here'!E5
A7: Planned Remaining | B7: ='Budget'!B73 | F7: BAH | G7: ='Start Here'!E6
A8: Minimum Savings Target | B8: ='Start Here'!H11 | F8: BAS | G8: ='Start Here'!E7
F9: Other | G9: ='Start Here'!E8
A11: Planned Budget Split
A12: Bucket | B12: Planned
A13: Housing | B13: ='Budget'!B16
A14: Food | B14: ='Budget'!B22
A15: Transportation | B15: ='Budget'!B30
A16: Health & Insurance | B16: ='Budget'!B36
A17: Debt Paydown | B17: ='Budget'!B42
A18: Savings & Investing | B18: ='Budget'!B50
A19: Wants & Lifestyle | B19: ='Budget'!B58
A20: Kids / Family | B20: ='Budget'!B64
A21: Other | B21: ='Budget'!B70
